---
manual:Javascript
version:0
lang:zh
rawUrl:https://developer.mozilla.org/zh-CN/docs/Web/JavaScript/Reference/Global_Objects/Promise/catch
---





**catch()**方法返回一个[Promise]11338 "")，并且处理拒绝的情况。它的行为与调用[`Promise.prototype.then(undefined, onRejected)`]41433 "then() 方法返回一个  Promise 。它最多需要有两个参数：Promise 的成功和失败情况的回调函数。")相同。 (事实上, calling`obj.catch(onRejected)`内部calls`obj.then(undefined, onRejected)`).


## 语法<a name="Syntax"></a>

```
p.catch(onRejected);

p.catch(function(reason) {
   // 拒绝
});

```

### 参数<a name="参数"></a>
<dl><dt id=''>**onRejected**</dt><dd>当Promise 被rejected时,被调用的一个[`Function`]40772 "此页面仍未被本地化, 期待您的翻译!")。 该函数拥有一个参数：</dd><dd>`reason`rejection 的原因。</dd><dd>

如果`onRejected`抛出一个错误或返回一个本身失败的 Promise ， 通过`catch()`返回的Promise 被rejected；否则，它将显示为成功（resolved）。


### 返回值<a name="返回值"></a>


一个[`Promise`]4107 "Promise 对象用于表示一个异步操作的最终状态（完成或失败），以及其返回的值。").

</dd></dl>
## 描述<a name="Description"></a>


`catch`方法可以用于您的promise组合中的错误处理。



Internally calls`Promise.prototype.then`on the object upon which is called, passing the parameters`undefined`and the`onRejected`handler received; then returns the value of that call (which is a[`Promise`]4107 "Promise 对象用于表示一个异步操作的最终状态（完成或失败），以及其返回的值。")).


## 示例<a name="示例"></a>

### 使用链式语句的`catch`方法<a name="使用链式语句的_catch方法"></a>

```
var p1 = new Promise(function(resolve, reject) {
  resolve('Success');
});

p1.then(function(value) {
  console.log(value); // "成功!"
  throw 'oh, no!';
}).catch(function(e) {
  console.log(e); // "oh, no!"
}).then(function(){
  console.log('after a catch the chain is restored');
}, function () {
  console.log('Not fired due to the catch');
});

// 以下行为与上述相同
p1.then(function(value) {
  console.log(value); // "成功!"
  return Promise.reject('oh, no!');
}).catch(function(e) {
  console.log(e); // "oh, no!"
}).then(function(){
  console.log('after a catch the chain is restored');
}, function () {
  console.log('Not fired due to the catch');
});
```

### 捕获抛出的错误<a name="捕获抛出的错误"></a>

```
// 抛出一个错误，大多数时候将调用catch方法
var p1 = new Promise(function(resolve, reject) {
  throw 'Uh-oh!';
});

p1.catch(function(e) {
  console.log(e); // "Uh-oh!"
});

// 在异步函数中抛出的错误不会被catch捕获到
var p2 = new Promise(function(resolve, reject) {
  setTimeout(function() {
    throw 'Uncaught Exception!';
  }, 1000);
});

p2.catch(function(e) {
  console.log(e); // 不会执行
});

// 在resolve()后面抛出的错误会被忽略
var p3 = new Promise(function(resolve, reject) {
  resolve();
  throw 'Silenced Exception!';
});

p3.catch(function(e) {
   console.log(e); // 不会执行
});
```

### 如果已决议<a name="如果已决议"></a>

```
//创建一个新的 Promise ，且已决议
var p1 = Promise.resolve("calling next");

var p2 = p1.catch(function (reason) {
    //这个方法永远不会调用
    console.log("catch p1!");
    console.log(reason);
});

p2.then(function (value) {
    console.log("next promise's onFulfilled"); /* next promise's onFulfilled */
    console.log(value); /* calling next */
}, function (reason) {
    console.log("next promise's onRejected");
    console.log(reason);
});
```

## 规范<a name="规范"></a>

规范 | 状态 | 备注 
[domenic/promises-unwrapping]45981 "") | Standard | Initial definition in an ECMA standard. 
[ECMAScript 2015 (6th Edition, ECMA-262)<br></br><small>Promise.prototype.catch</small>]45982 "") | Standard |  


## 浏览器兼容性<a name="浏览器兼容性"></a>


No compatibility data found. Please contribute data for &quot;javascript/promise&quot; (depth: Promise.prototype.catch) to the[MDN compatibility data repository]3344 "").


## 相关链接<a name="相关链接"></a>

* [`Promise`]4107 "Promise 对象用于表示一个异步操作的最终状态（完成或失败），以及其返回的值。")
* [`Promise.prototype.then()`]41433 "then() 方法返回一个  Promise 。它最多需要有两个参数：Promise 的成功和失败情况的回调函数。")



