---
manual:Javascript
version:0
lang:zh
rawUrl:https://developer.mozilla.org/zh-CN/docs/Web/JavaScript/Reference/Global_Objects/Generator/throw
---





`**throw**`**`()`**方法用来向生成器抛出异常，并恢复生成器的执行，返回带有`done`及`value`两个属性的对象。


## 语法<a name="Syntax"></a>

```
gen.throw(exception)
```

### 参数<a name="参数"></a>
<dl><dt id=''>`exception`</dt><dd>用于抛出的异常。 使用[`Error`]10494 "通过Error的构造器可以创建一个错误对象。当运行时错误产生时，Error的实例对象会被抛出。Error对象也可用于用户自定义的异常的基础对象。下面列出了各种内建的标准错误类型。")的实例对调试非常有帮助.</dd></dl>
### 返回值<a name="返回值"></a>


带有两个属性的[`对象`]10219 "Object 构造函数创建一个对象包装器。")：


* `done`(boolean)
	* 如果迭代器已经返回了迭代序列的末尾，则值为`true`。在这种情况下，`可以`指定迭代器`value`的返回值。
	* 如果迭代能够继续生产在序列中的下一个值，则值为`false`。 这相当与不指定 done 属性的值。
* `value`- 迭代器返回的任何 JavaScript 值。当 done 是 true 的时候可以省略。

## 示例<a name="示例"></a>

### 使用`throw()`<a name="Example:_Using_test"></a>


下面的例子展示了一个简单的生成器并使用throw方法向该生成器抛出一个异常，该异常通常可以通过`[try...catch]25469 "")`块进行捕获.


```
function* gen() {
  while(true) {
    try {
       yield 42;
    } catch(e) {
      console.log("Error caught!");
    }
  }
}

var g = gen();
g.next(); // { value: 42, done: false }
g.throw(new Error("Something went wrong")); // "Error caught!"
```

## 规范<a name="Specifications"></a>

Specification | Status | Comment 
[ECMAScript 2015 (6th Edition, ECMA-262)<br></br><small>Generator.prototype.throw</small>]44740 "") | Standard | Initial definition. 
[ECMAScript Latest Draft (ECMA-262)<br></br><small>Generator.prototype.throw</small>]44741 "") | Draft |  


## 浏览器兼容性<a name="Browser_compatibility"></a>


**[We&#39;re converting our compatibility data into a machine-readable JSON format]3344 "")**. This compatibility table still uses the old format, because we haven&#39;t yet converted the data it contains.**[Find out how you can help!]3392 "")**


* 
* 

Feature | Chrome | Firefox (Gecko) | Internet Explorer | Opera | Safari 
Basic support | ? | [26]12083 "Released on 2013-12-10.")(26) | ? | ? | ? 





## 相关链接<a name="See_also"></a>

* `[function*]40932 "")`



